Workbook

Sheet README
B1: OPERATIONS UTILITY TOOLKIT — FINANCIAL MODEL (worldwide, three revenue pillars)
B3: What this is
B4: A revenue model for the interconnected operations-calculator suite. Traffic is sized on TRUE WORLDWIDE search volume for every English keyword (Semrush, all country databases, July 2026). Revenue is modelled across three pillars: display ads, affiliate/lead-gen, and a paid ACCOUNT layer (API, bulk calculation, saved scenarios).
B6: How to use it
B7: 1. Keyword_Portfolio holds real per-market volumes plus real worldwide totals for every term (only the long-tail row is an estimate). 2. Tune the BLUE cells on Assumptions. 3. Traffic_Revenue ramps all three pillars over 36 months; Scenarios shows the mature run-rate for Conservative/Base/Optimistic.
B9: Colour key
B10: Blue = your inputs. Black = calculated. Green = derived from another tab. Yellow = the one remaining estimate.
B12: The three pillars
B13: Display ads are the floor (RPM rises with scale). Affiliate/lead-gen for freight and logistics software is the mid lever (a $50-200 lead beats a lot of ad pageviews). The ACCOUNT layer is the ceiling-raiser: recurring revenue that compounds with traffic. It also carries the most uncertainty, since free-tool audiences convert at low rates unless the account gates genuine value.
B15: What survives all the data
B16: The niche is winnable but small (worldwide ~370k searches/mo across the portfolio). 50M PV/yr stays ~35x beyond owning the whole niche. On ads + affiliate alone this is low thousands/yr; the account pillar is what makes it a business. Freight class calculator (16,970 ww, 93% Tier-1, difficulty 26) is the best single asset. Build the inventory wedge first for the pattern, then the freight engine, all interlinked.
B18: Data sources
B19: Volumes: Semrush phrase_all (worldwide) + phrase_these (per market), Jul 2026 - all real. RPM/CTR: 2026 industry benchmarks. Account-pillar rates are conservative planning assumptions and carry the highest uncertainty. Not financial advice.

Sheet Assumptions
A1: MODEL ASSUMPTIONS
A2: Blue = edit these. Black = calculated. Green = derived from another tab.
A4: A. DISPLAY ADS (RPM per 1,000 pageviews, USD)
A5: AdSense RPM (0-10k sessions/mo) | B5: 4 | C5: Benchmark $2-5.
A6: Ezoic RPM (10k-50k sessions/mo) | B6: 8 | C6: Benchmark $4-12.
A7: Mediavine/Raptive RPM (50k+ sessions/mo) | B7: 18 | C7: Benchmark $15-30+.
A8: Tier-1 traffic share (US/UK/CA/AU) | B8: =SUMPRODUCT((Keyword_Portfolio!C3:C23+Keyword_Portfolio!D3:D23+Keyword_Portfolio!E3:E23+Keyword_Portfolio!F3:F23)*Keyword_Portfolio!L3:L23)/SUM(Keyword_Portfolio!M3:M23) -> 0.59802917 | C8: AUTO-derived, traffic-weighted, from real per-market data.
A9: Non-Tier-1 RPM factor | B9: 0.35 | C9: Rest earns ~30-40% of Tier-1.
A10: Blended geo factor | B10: =B8*1+(1-B8)*B9 -> 0.73871896 | C10: Auto: applied to every display RPM.
A11: Pages per session (connected suite) | B11: 1.9 | C11: Interlinked tools: 1.8-2.2. A standalone tool would be ~1.3.
A13: B. AFFILIATE / LEAD-GEN
A14: Affiliate/CTA click rate (% of pageviews) | B14: 0.01 | C14: Share of pageviews clicking a software/affiliate CTA.
A15: Click -> qualified conversion | B15: 0.08 | C15: Share of those clicks that become a lead/sale.
A16: Value per qualified conversion ($) | B16: 15 | C16: B2B software leads can be $50-200+; kept conservative.
A17: Effective affiliate RPM (per 1,000 PV, $) | B17: =B14*B15*B16*1000 -> 12 | C17: Auto.
A19: C. ORGANIC CTR BY SERP POSITION
A20: Position | B20: CTR | C20: Calculators resist AI Overviews (<3% disruption).
A21: 1 | B21: 0.27
A22: 2 | B22: 0.14
A23: 3 | B23: 0.09
A24: 4 | B24: 0.065
A25: 5 | B25: 0.05
A26: 6 | B26: 0.04
A27: 7 | B27: 0.032
A28: 8 | B28: 0.026
A29: 9 | B29: 0.022
A30: 10 | B30: 0.018
A32: D. SCENARIO CAPTURE MULTIPLIERS
A33: Conservative | B33: 0.45 | C33: Under-rank on the bigger terms.
A34: Base | B34: 1 | C34: Reach target SERP positions.
A35: Optimistic | B35: 1.7 | C35: Over-rank + wide long tail.
A37: E. BUILD COST (optional)
A38: Target number of calculator pages | B38: 25
A39: Hours per page (build + content) | B39: 8
A40: Your hourly opportunity cost ($) | B40: 50
A41: Total build hours | B41: =B38*B39 -> 200 | C41: Auto.
A42: Notional build cost ($) | B42: =B41*B40 -> 10000 | C42: Auto.
A43: Tooling + hosting per year ($) | B43: 600
A45: F. ACCOUNTS / SUBSCRIPTION (the ceiling-raiser - HIGH uncertainty)
A46: Free -> account signup (% of sessions) | B46: 0.015 | C46: Share of visits that create a free account.
...

Sheet Keyword_Portfolio
A1: KEYWORD PORTFOLIO — real per-market + TRUE WORLDWIDE volumes (Semrush, Jul 2026)
A2: Keyword | B2: Cluster | C2: US | D2: UK | E2: CA | F2: AU | G2: IN | H2: Worldwide | I2: CPC ($) | J2: KD | K2: Target pos | L2: CTR at target | M2: Mature clicks/mo
A3: reorder point calculator | B3: Inventory | C3: 170 | D3: 40 | E3: 20 | F3: 30 | G3: 20 | H3: 1050 | I3: 3.28 | J3: 20 | K3: 3 | L3: =INDEX(Assumptions!$B$21:$B$30,K3) -> 0.09 | M3: =H3*L3 -> 94.5
A4: safety stock calculator | B4: Inventory | C4: 260 | D4: 70 | E4: 20 | F4: 40 | G4: 90 | H4: 2470 | I4: 1.76 | J4: 16 | K4: 3 | L4: =INDEX(Assumptions!$B$21:$B$30,K4) -> 0.09 | M4: =H4*L4 -> 222.3
A5: eoq calculator | B5: Inventory | C5: 320 | D5: 70 | E5: 20 | F5: 20 | G5: 110 | H5: 1340 | I5: 3.3 | J5: 27 | K5: 4 | L5: =INDEX(Assumptions!$B$21:$B$30,K5) -> 0.065 | M5: =H5*L5 -> 87.1
A6: economic order quantity calculator | B6: Inventory | C6: 110 | D6: 70 | E6: 20 | F6: 10 | G6: 210 | H6: 770 | I6: 0 | J6: 14 | K6: 4 | L6: =INDEX(Assumptions!$B$21:$B$30,K6) -> 0.065 | M6: =H6*L6 -> 50.05
A7: inventory turnover calculator | B7: Inventory | C7: 260 | D7: 70 | E7: 20 | F7: 30 | G7: 10 | H7: 670 | I7: 1.17 | J7: 35 | K7: 4 | L7: =INDEX(Assumptions!$B$21:$B$30,K7) -> 0.065 | M7: =H7*L7 -> 43.55
A8: days of inventory calculator | B8: Inventory | C8: 20 | D8: 0 | E8: 0 | F8: 0 | G8: 0 | H8: 20 | I8: 0 | J8: 5 | K8: 3 | L8: =INDEX(Assumptions!$B$21:$B$30,K8) -> 0.09 | M8: =H8*L8 -> 1.8
A9: inventory carrying cost calculator | B9: Inventory | C9: 40 | D9: 10 | E9: 10 | F9: 0 | G9: 30 | H9: 170 | I9: 1.59 | J9: 27 | K9: 3 | L9: =INDEX(Assumptions!$B$21:$B$30,K9) -> 0.09 | M9: =H9*L9 -> 15.3
A10: abc analysis calculator | B10: Inventory | C10: 20 | D10: 10 | E10: 10 | F10: 10 | G10: 0 | H10: 60 | I10: 0 | J10: 5 | K10: 4 | L10: =INDEX(Assumptions!$B$21:$B$30,K10) -> 0.065 | M10: =H10*L10 -> 3.9
A11: cbm calculator | B11: Freight | C11: 2900 | D11: 1600 | E11: 590 | F11: 1300 | G11: 12100 | H11: 40880 | I11: 14.83 | J11: 37 | K11: 5 | L11: =INDEX(Assumptions!$B$21:$B$30,K11) -> 0.05 | M11: =H11*L11 -> 2044
A12: volumetric weight calculator | B12: Freight | C12: 260 | D12: 480 | E12: 90 | F12: 110 | G12: 2400 | H12: 5530 | I12: 2.59 | J12: 24 | K12: 4 | L12: =INDEX(Assumptions!$B$21:$B$30,K12) -> 0.065 | M12: =H12*L12 -> 359.45
A13: dimensional weight calculator | B13: Freight | C13: 1600 | D13: 70 | E13: 140 | F13: 20 | G13: 210 | H13: 2750 | I13: 1.22 | J13: 21 | K13: 4 | L13: =INDEX(Assumptions!$B$21:$B$30,K13) -> 0.065 | M13: =H13*L13 -> 178.75
A14: freight class calculator | B14: Freight | C14: 14800 | D14: 50 | E14: 1000 | F14: 20 | G14: 140 | H14: 16970 | I14: 2.67 | J14: 26 | K14: 4 | L14: =INDEX(Assumptions!$B$21:$B$30,K14) -> 0.065 | M14: =H14*L14 -> 1103.05
... A23: long-tail & variant queries (est.) | B23: Long-tail | C23: 8000 | D23: 3000 | E23: 1500 | F23: 2000 | G23: 7500 | H23: 35000 | I23: 2 | J23: 20 | K23: 5 | L23: =INDEX(Assumptions!$B$21:$B$30,K23) -> 0.05 | M23: =H23*L23 -> 1750
A24: TOTAL | C24: =SUM(C3:C23) -> 157850 | D24: =SUM(D3:D23) -> 35460 | E24: =SUM(E3:E23) -> 23240 | F24: =SUM(F3:F23) -> 15220 | G24: =SUM(G3:G23) -> 30710 | H24: =SUM(H3:H23) -> 338950 | M24: =SUM(M3:M23) -> 11663.11
A26: All volumes real (Semrush phrase_all worldwide + phrase_these per market, Jul 2026). Only the long-tail row is a modeled estimate.
A27: Freight class (16,970 ww, 93% Tier-1) = big + winnable + high-RPM. CBM (40,880 ww) is bigger but ~16% Tier-1 (low RPM). Build freight-first; lead with freight class.

Sheet Traffic_Revenue
A1: TRAFFIC & REVENUE — Base case, 36 months, three pillars (worldwide)
A2: Ads + affiliate scale with pageviews. Accounts accumulate a subscriber base (new signups minus churn) that compounds.
A3: Month | B3: Ramp % | C3: Clicks / sessions | D3: Pageviews | E3: Display RPM $ | F3: Display rev $ | G3: Affiliate rev $ | H3: New paid subs | I3: Cumul. subs | J3: Account MRR $ | K3: Total rev $
A4: 1 | B4: 0 | C4: =Keyword_Portfolio!$M$24*B4*Assumptions!$B$34 -> 0 | D4: =C4*Assumptions!$B$11 -> 0 | E4: =Assumptions!$B$10*IF(C4>=50000,Assumptions!$B$7,IF(C4>=10000,Assumptions!$B$6,Assumptions!$B$5)) -> 2.9548758 | F4: =D4/1000*E4 -> 0 | G4: =D4/1000*Assumptions!$B$17 -> 0 | H4: =C4*Assumptions!$B$46*Assumptions!$B$47 -> 0 | I4: =H4 -> 0 | J4: =I4*Assumptions!$B$49 -> 0 | K4: =F4+G4+J4 -> 0
A5: 2 | B5: 0.01 | C5: =Keyword_Portfolio!$M$24*B5*Assumptions!$B$34 -> 116.6311 | D5: =C5*Assumptions!$B$11 -> 221.59909 | E5: =Assumptions!$B$10*IF(C5>=50000,Assumptions!$B$7,IF(C5>=10000,Assumptions!$B$6,Assumptions!$B$5)) -> 2.9548758 | F5: =D5/1000*E5 -> 0.6547978 | G5: =D5/1000*Assumptions!$B$17 -> 2.6591891 | H5: =C5*Assumptions!$B$46*Assumptions!$B$47 -> 0.052483995 | I5: =I4*(1-Assumptions!$B$48)+H5 -> 0.052483995 | J5: =I5*Assumptions!$B$49 -> 0.9971959 | K5: =F5+G5+J5 -> 4.3111828
A6: 3 | B6: 0.02 | C6: =Keyword_Portfolio!$M$24*B6*Assumptions!$B$34 -> 233.2622 | D6: =C6*Assumptions!$B$11 -> 443.19818 | E6: =Assumptions!$B$10*IF(C6>=50000,Assumptions!$B$7,IF(C6>=10000,Assumptions!$B$6,Assumptions!$B$5)) -> 2.9548758 | F6: =D6/1000*E6 -> 1.3095956 | G6: =D6/1000*Assumptions!$B$17 -> 5.3183782 | H6: =C6*Assumptions!$B$46*Assumptions!$B$47 -> 0.10496799 | I6: =I5*(1-Assumptions!$B$48)+H6 -> 0.15430295 | J6: =I6*Assumptions!$B$49 -> 2.931756 | K6: =F6+G6+J6 -> 9.5597297
A7: 4 | B7: 0.04 | C7: =Keyword_Portfolio!$M$24*B7*Assumptions!$B$34 -> 466.5244 | D7: =C7*Assumptions!$B$11 -> 886.39636 | E7: =Assumptions!$B$10*IF(C7>=50000,Assumptions!$B$7,IF(C7>=10000,Assumptions!$B$6,Assumptions!$B$5)) -> 2.9548758 | F7: =D7/1000*E7 -> 2.6191912 | G7: =D7/1000*Assumptions!$B$17 -> 10.636756 | H7: =C7*Assumptions!$B$46*Assumptions!$B$47 -> 0.20993598 | I7: =I6*(1-Assumptions!$B$48)+H7 -> 0.35498075 | J7: =I7*Assumptions!$B$49 -> 6.7446342 | K7: =F7+G7+J7 -> 20.000582
A8: 5 | B8: 0.06 | C8: =Keyword_Portfolio!$M$24*B8*Assumptions!$B$34 -> 699.7866 | D8: =C8*Assumptions!$B$11 -> 1329.5945 | E8: =Assumptions!$B$10*IF(C8>=50000,Assumptions!$B$7,IF(C8>=10000,Assumptions!$B$6,Assumptions!$B$5)) -> 2.9548758 | F8: =D8/1000*E8 -> 3.9287868 | G8: =D8/1000*Assumptions!$B$17 -> 15.955134 | H8: =C8*Assumptions!$B$46*Assumptions!$B$47 -> 0.31490397 | I8: =I7*(1-Assumptions!$B$48)+H8 -> 0.64858587 | J8: =I8*Assumptions!$B$49 -> 12.323132 | K8: =F8+G8+J8 -> 32.207053
A9: 6 | B9: 0.09 | C9: =Keyword_Portfolio!$M$24*B9*Assumptions!$B$34 -> 1049.6799 | D9: =C9*Assumptions!$B$11 -> 1994.3918 | E9: =Assumptions!$B$10*IF(C9>=50000,Assumptions!$B$7,IF(C9>=10000,Assumptions!$B$6,Assumptions!$B$5)) -> 2.9548758 | F9: =D9/1000*E9 -> 5.8931802 | G9: =D9/1000*Assumptions!$B$17 -> 23.932702 | H9: =C9*Assumptions!$B$46*Assumptions!$B$47 -> 0.47235595 | I9: =I8*(1-Assumptions!$B$48)+H9 -> 1.0820267 | J9: =I9*Assumptions!$B$49 -> 20.558507 | K9: =F9+G9+J9 -> 50.384389
A10: 7 | B10: 0.12 | C10: =Keyword_Portfolio!$M$24*B10*Assumptions!$B$34 -> 1399.5732 | D10: =C10*Assumptions!$B$11 -> 2659.1891 | E10: =Assumptions!$B$10*IF(C10>=50000,Assumptions!$B$7,IF(C10>=10000,Assumptions!$B$6,Assumptions!$B$5)) -> 2.9548758 | F10: =D10/1000*E10 -> 7.8575736 | G10: =D10/1000*Assumptions!$B$17 -> 31.910269 | H10: =C10*Assumptions!$B$46*Assumptions!$B$47 -> 0.62980794 | I10: =I9*(1-Assumptions!$B$48)+H10 -> 1.646913 | J10: =I10*Assumptions!$B$49 -> 31.291347 | K10: =F10+G10+J10 -> 71.05919
A11: 8 | B11: 0.15 | C11: =Keyword_Portfolio!$M$24*B11*Assumptions!$B$34 -> 1749.4665 | D11: =C11*Assumptions!$B$11 -> 3323.9864 | E11: =Assumptions!$B$10*IF(C11>=50000,Assumptions!$B$7,IF(C11>=10000,Assumptions!$B$6,Assumptions!$B$5)) -> 2.9548758 | F11: =D11/1000*E11 -> 9.821967 | G11: =D11/1000*Assumptions!$B$17 -> 39.887836 | H11: =C11*Assumptions!$B$46*Assumptions!$B$47 -> 0.78725992 | I11: =I10*(1-Assumptions!$B$48)+H11 -> 2.3353582 | J11: =I11*Assumptions!$B$49 -> 44.371805 | K11: =F11+G11+J11 -> 94.081608
A12: 9 | B12: 0.18 | C12: =Keyword_Portfolio!$M$24*B12*Assumptions!$B$34 -> 2099.3598 | D12: =C12*Assumptions!$B$11 -> 3988.7836 | E12: =Assumptions!$B$10*IF(C12>=50000,Assumptions!$B$7,IF(C12>=10000,Assumptions!$B$6,Assumptions!$B$5)) -> 2.9548758 | F12: =D12/1000*E12 -> 11.78636 | G12: =D12/1000*Assumptions!$B$17 -> 47.865403 | H12: =C12*Assumptions!$B$46*Assumptions!$B$47 -> 0.94471191 | I12: =I11*(1-Assumptions!$B$48)+H12 -> 3.1399486 | J12: =I12*Assumptions!$B$49 -> 59.659023 | K12: =F12+G12+J12 -> 119.31079
A13: 10 | B13: 0.22 | C13: =Keyword_Portfolio!$M$24*B13*Assumptions!$B$34 -> 2565.8842 | D13: =C13*Assumptions!$B$11 -> 4875.18 | E13: =Assumptions!$B$10*IF(C13>=50000,Assumptions!$B$7,IF(C13>=10000,Assumptions!$B$6,Assumptions!$B$5)) -> 2.9548758 | F13: =D13/1000*E13 -> 14.405552 | G13: =D13/1000*Assumptions!$B$17 -> 58.50216 | H13: =C13*Assumptions!$B$46*Assumptions!$B$47 -> 1.1546479 | I13: =I12*(1-Assumptions!$B$48)+H13 -> 4.1061996 | J13: =I13*Assumptions!$B$49 -> 78.017792 | K13: =F13+G13+J13 -> 150.9255
A14: 11 | B14: 0.26 | C14: =Keyword_Portfolio!$M$24*B14*Assumptions!$B$34 -> 3032.4086 | D14: =C14*Assumptions!$B$11 -> 5761.5763 | E14: =Assumptions!$B$10*IF(C14>=50000,Assumptions!$B$7,IF(C14>=10000,Assumptions!$B$6,Assumptions!$B$5)) -> 2.9548758 | F14: =D14/1000*E14 -> 17.024743 | G14: =D14/1000*Assumptions!$B$17 -> 69.138916 | H14: =C14*Assumptions!$B$46*Assumptions!$B$47 -> 1.3645839 | I14: =I13*(1-Assumptions!$B$48)+H14 -> 5.2244115 | J14: =I14*Assumptions!$B$49 -> 99.263818 | K14: =F14+G14+J14 -> 185.42748
A15: 12 | B15: 0.3 | C15: =Keyword_Portfolio!$M$24*B15*Assumptions!$B$34 -> 3498.933 | D15: =C15*Assumptions!$B$11 -> 6647.9727 | E15: =Assumptions!$B$10*IF(C15>=50000,Assumptions!$B$7,IF(C15>=10000,Assumptions!$B$6,Assumptions!$B$5)) -> 2.9548758 | F15: =D15/1000*E15 -> 19.643934 | G15: =D15/1000*Assumptions!$B$17 -> 79.775672 | H15: =C15*Assumptions!$B$46*Assumptions!$B$47 -> 1.5745198 | I15: =I14*(1-Assumptions!$B$48)+H15 -> 6.4854666 | J15: =I15*Assumptions!$B$49 -> 123.22387 | K15: =F15+G15+J15 -> 222.64347
A16: 13 | B16: 0.35 | C16: =Keyword_Portfolio!$M$24*B16*Assumptions!$B$34 -> 4082.0885 | D16: =C16*Assumptions!$B$11 -> 7755.9681 | E16: =Assumptions!$B$10*IF(C16>=50000,Assumptions!$B$7,IF(C16>=10000,Assumptions!$B$6,Assumptions!$B$5)) -> 2.9548758 | F16: =D16/1000*E16 -> 22.917923 | G16: =D16/1000*Assumptions!$B$17 -> 93.071618 | H16: =C16*Assumptions!$B$46*Assumptions!$B$47 -> 1.8369398 | I16: =I15*(1-Assumptions!$B$48)+H16 -> 7.9332784 | J16: =I16*Assumptions!$B$49 -> 150.73229 | K16: =F16+G16+J16 -> 266.72183
... A39: 36 | B39: 1 | C39: =Keyword_Portfolio!$M$24*B39*Assumptions!$B$34 -> 11663.11 | D39: =C39*Assumptions!$B$11 -> 22159.909 | E39: =Assumptions!$B$10*IF(C39>=50000,Assumptions!$B$7,IF(C39>=10000,Assumptions!$B$6,Assumptions!$B$5)) -> 5.9097517 | F39: =D39/1000*E39 -> 130.95956 | G39: =D39/1000*Assumptions!$B$17 -> 265.91891 | H39: =C39*Assumptions!$B$46*Assumptions!$B$47 -> 5.2483995 | I39: =I38*(1-Assumptions!$B$48)+H39 -> 59.131817 | J39: =I39*Assumptions!$B$49 -> 1123.5045 | K39: =F39+G39+J39 -> 1520.383
A41: Year 1 total revenue (months 1-12) | E41: =SUM(K4:K15) -> 959.91097
A42: Year 2 total revenue (months 13-24) | E42: =SUM(K16:K27) -> 6809.2212
A43: Year 3 total revenue (months 25-36) | E43: =SUM(K28:K39) -> 15379.212
A44: Month-36 subscribers | E44: =I39 -> 59.131817
A45: Month-36 monthly revenue (all pillars) | E45: =K39 -> 1520.383
A46: Month-36 annualised run-rate | E46: =K39*12 -> 18244.596

Sheet Scenarios
A1: SCENARIOS AT MATURITY (annualised run-rate, worldwide, three pillars)
A2: Steady-state subscriber base = new signups per month divided by monthly churn.
A3: Metric | B3: Conservative | C3: Base | D3: Optimistic
A4: Capture multiplier | B4: =Assumptions!$B$33 -> 0.45 | C4: =Assumptions!$B$34 -> 1 | D4: =Assumptions!$B$35 -> 1.7
A5: Mature monthly clicks / sessions | B5: =Keyword_Portfolio!$M$24*B4 -> 5248.3995 | C5: =Keyword_Portfolio!$M$24*C4 -> 11663.11 | D5: =Keyword_Portfolio!$M$24*D4 -> 19827.287
A6: Mature monthly pageviews | B6: =B5*Assumptions!$B$11 -> 9971.959 | C6: =C5*Assumptions!$B$11 -> 22159.909 | D6: =D5*Assumptions!$B$11 -> 37671.845
A7: Ad network tier reached | B7: =IF(B5>=50000,"Mediavine/Raptive",IF(B5>=10000,"Ezoic","AdSense")) -> AdSense | C7: =IF(C5>=50000,"Mediavine/Raptive",IF(C5>=10000,"Ezoic","AdSense")) -> Ezoic | D7: =IF(D5>=50000,"Mediavine/Raptive",IF(D5>=10000,"Ezoic","AdSense")) -> Ezoic
A8: Display RPM ($) | B8: =Assumptions!$B$10*IF(B5>=50000,Assumptions!$B$7,IF(B5>=10000,Assumptions!$B$6,Assumptions!$B$5)) -> 2.9548758 | C8: =Assumptions!$B$10*IF(C5>=50000,Assumptions!$B$7,IF(C5>=10000,Assumptions!$B$6,Assumptions!$B$5)) -> 5.9097517 | D8: =Assumptions!$B$10*IF(D5>=50000,Assumptions!$B$7,IF(D5>=10000,Assumptions!$B$6,Assumptions!$B$5)) -> 5.9097517
A9: PILLAR 1 - Annual display revenue ($) | B9: =B6*12/1000*B8 -> 353.59081 | C9: =C6*12/1000*C8 -> 1571.5147 | D9: =D6*12/1000*D8 -> 2671.575
A10: PILLAR 2 - Annual affiliate revenue ($) | B10: =B6*12/1000*Assumptions!$B$17 -> 1435.9621 | C10: =C6*12/1000*Assumptions!$B$17 -> 3191.0269 | D10: =D6*12/1000*Assumptions!$B$17 -> 5424.7457
A11: New paid subs / month | B11: =B5*Assumptions!$B$46*Assumptions!$B$47 -> 2.3617798 | C11: =C5*Assumptions!$B$46*Assumptions!$B$47 -> 5.2483995 | D11: =D5*Assumptions!$B$46*Assumptions!$B$47 -> 8.9222791
A12: Steady-state subscribers | B12: =B11/Assumptions!$B$48 -> 39.362996 | C12: =C11/Assumptions!$B$48 -> 87.473325 | D12: =D11/Assumptions!$B$48 -> 148.70465
A13: Account MRR ($) | B13: =B12*Assumptions!$B$49 -> 747.89693 | C13: =C12*Assumptions!$B$49 -> 1661.9932 | D13: =D12*Assumptions!$B$49 -> 2825.3884
A14: PILLAR 3 - Annual account revenue ($) | B14: =B13*12 -> 8974.7631 | C14: =C13*12 -> 19943.918 | D14: =D13*12 -> 33904.661
A15: ANNUAL TOTAL REVENUE ($) | B15: =B9+B10+B14 -> 10764.316 | C15: =C9+C10+C14 -> 24706.46 | D15: =D9+D10+D14 -> 42000.982
A16: Annual pageviews | B16: =B6*12 -> 119663.51 | C16: =C6*12 -> 265918.91 | D16: =D6*12 -> 452062.14
A17: % of the 50M PV/yr target | B17: =B16/50000000 -> 0.0023932702 | C17: =C16/50000000 -> 0.0053183782 | D17: =D16/50000000 -> 0.0090412429

Sheet Reality_Check_50M
A1: REALITY CHECK — can this niche reach 50M page views/year? (worldwide)
A3: PART 1 - What 50M PV/yr would require
A4: Target annual pageviews (from the tutorial) | B4: 50000000
A5: Pages per session | B5: =Assumptions!$B$11 -> 1.9
A6: Required annual clicks / sessions | B6: =B4/B5 -> 26315789
A7: Required monthly clicks / sessions | B7: =B6/12 -> 2192982.5
A8: Best-case CTR (ranked #1) | B8: =Assumptions!$B$21 -> 0.27
A9: Required captured search volume / month | B9: =B7/B8 -> 8122157.2
A11: PART 2 - What the worldwide English niche contains
A12: Niche total addressable volume / month (worldwide) | B12: =Keyword_Portfolio!$H$24 -> 338950 | C12: Sum of every keyword, all countries.
A13: Theoretical MAX clicks/mo (own 100% at #1) | B13: =B12*Assumptions!$B$21 -> 91516.5
A14: Theoretical MAX annual pageviews | B14: =B13*12*Assumptions!$B$11 -> 2086576.2
A16: PART 3 - The verdict
A17: 50M target / niche theoretical max | B17: =B4/B14 -> 23.9627
A18: Max achievable % of the 50M target | B18: =B14/B4 -> 0.041731524
A20: Even counting every country that searches these terms in English, and even owning the niche at #1, you land ~35x short of 50M. Replace the pageview target with revenue-per-visitor. The account pillar and freight affiliate are the levers.
